---
created: '2025-10-19'
last_reviewed: '2025-10-19'
next_review: '2025-10-19'
review_count: 0
difficulty: medium
mastery_level: 0.0
tags:
- C++
- C++/析构函数可以抛出异常么.md
related_outlines: []
---

# 析构函数可以抛出异常么？

## 面试标准答案（可背诵）

**析构函数技术上可以抛出异常，但强烈不建议这样做。** 主要原因有三点：
1. **栈展开风险**：如果在异常处理的栈展开过程中，析构函数再次抛出异常，会导致双重异常，程序将调用`std::terminate()`直接终止
2. **资源泄漏**：析构函数是释放资源的最后机会，如果因异常而中断，可能导致资源泄漏
3. **违反设计原则**：C++11起析构函数默认是`noexcept`，抛出异常会违反这一约定

**正确做法**是在析构函数内部捕获并处理所有可能的异常，绝不让异常逃逸出析构函数。

---

## 详细解析

### 1. 为什么析构函数不应该抛出异常？

#### 1.1 双重异常问题

当异常发生时，C++会进行**栈展开（Stack Unwinding）**，自动调用栈上对象的析构函数来清理资源。如果在这个过程中，某个析构函数又抛出了异常，就会出现两个同时活跃的异常：

```cpp
class BadClass {
public:
    ~BadClass() {
        throw std::runtime_error("析构函数抛出异常"); // 危险！
    }
};

void dangerous_function() {
    BadClass obj;
    throw std::runtime_error("第一个异常");
    // 栈展开时调用~BadClass()，又抛出第二个异常
    // 结果：std::terminate()被调用，程序崩溃
}
```

**结果**：程序会调用`std::terminate()`，默认行为是调用`std::abort()`终止程序，无法被捕获。

#### 1.2 资源泄漏风险

析构函数的主要职责是释放对象持有的资源（内存、文件句柄、网络连接等）。如果析构函数因异常而提前退出，后续的清理代码将无法执行：

```cpp
class FileHandler {
    FILE* file;
public:
    ~FileHandler() {
        if (some_condition) {
            throw std::exception(); // 异常发生
        }
        fclose(file); // 这行代码永远不会执行！文件句柄泄漏
    }
};
```

#### 1.3 违反noexcept约定

从C++11开始，析构函数默认被隐式声明为`noexcept(true)`。如果析构函数抛出异常，会违反这个约定，同样导致`std::terminate()`被调用。

```cpp
class MyClass {
public:
    ~MyClass() noexcept {  // 默认就是noexcept
        throw std::exception(); // 违反noexcept，调用std::terminate()
    }
};
```

### 2. 正确的做法

#### 2.1 捕获并处理所有异常

在析构函数内部使用try-catch捕获所有可能的异常：

```cpp
class SafeClass {
    std::string log_file;
public:
    ~SafeClass() noexcept {
        try {
            // 可能抛出异常的清理操作
            write_log(log_file);
            close_connections();
        } catch (const std::exception& e) {
            // 记录错误但不抛出
            std::cerr << "析构函数中发生错误: " << e.what() << std::endl;
        } catch (...) {
            // 捕获所有其他异常
            std::cerr << "析构函数中发生未知错误" << std::endl;
        }
        // 继续其他清理工作
    }
};
```

#### 2.2 提供单独的清理函数

对于可能失败的操作，提供一个单独的清理函数让用户显式调用，析构函数只处理保证不会失败的操作：

```cpp
class DatabaseConnection {
    bool closed = false;
public:
    // 显式关闭函数，可以抛出异常
    void close() {
        if (!closed) {
            commit_transaction(); // 可能抛出异常
            disconnect(); // 可能抛出异常
            closed = true;
        }
    }
    
    // 析构函数：确保资源被释放，但不抛出异常
    ~DatabaseConnection() noexcept {
        if (!closed) {
            try {
                rollback_transaction(); // 回滚而不是提交
                disconnect();
            } catch (...) {
                // 吞掉异常，确保不会传播
            }
        }
    }
};

// 使用方式
void use_database() {
    DatabaseConnection conn;
    try {
        // 执行数据库操作
        conn.close(); // 显式关闭，可以处理异常
    } catch (const std::exception& e) {
        // 处理close()抛出的异常
    }
    // 如果忘记调用close()，析构函数会做最后的清理
}
```

### 3. 实际案例

标准库中的设计遵循这一原则：

```cpp
// std::fstream的析构函数不会抛出异常
std::ofstream file("data.txt");
file << "some data";
// file.close(); // 可能抛出异常
// ~ofstream() 不会抛出异常，但可能丢失数据
```

如果需要确保数据被正确写入，应该显式调用`close()`并处理可能的异常。

### 4. 总结要点

| 方面          | 说明                                     |
| ------------- | ---------------------------------------- |
| **是否可以**  | 语法上可以，但强烈不推荐                 |
| **主要风险**  | 双重异常导致`std::terminate()`、资源泄漏 |
| **C++11规则** | 析构函数默认`noexcept(true)`             |
| **最佳实践**  | 在析构函数内捕获所有异常，不让异常逃逸   |
| **设计模式**  | 提供显式清理函数处理可能失败的操作       |

**记住**：析构函数是资源清理的最后防线，必须保证它的执行不会失败，这是C++ RAII（资源获取即初始化）原则的核心要求。

